2019-06-27 16:39:59 logger.py[line:96] DEBUG =================扫描程序开始==========================
2019-06-27 16:40:10 logger.py[line:90] ERROR HTTPConnectionPool(host='chrome', port=4444): Max retries exceeded with url: /wd/hub/session (Caused by NewConnectionError('<urllib3.connection.HTTPConnection object at 0x0000022480333C88>: Failed to establish a new connection: [Errno 11001] getaddrinfo failed'))
2019-06-27 16:40:15 logger.py[line:90] ERROR 请检查好Chrome环境！
2019-06-27 16:42:03 logger.py[line:96] DEBUG =================扫描程序开始==========================
2019-06-27 16:42:15 logger.py[line:90] ERROR HTTPConnectionPool(host='chrome', port=4444): Max retries exceeded with url: /wd/hub/session (Caused by NewConnectionError('<urllib3.connection.HTTPConnection object at 0x000001465CB7B7B8>: Failed to establish a new connection: [Errno 11001] getaddrinfo failed'))
2019-06-27 16:42:19 logger.py[line:90] ERROR 请检查好Chrome环境！
2019-06-27 16:43:05 logger.py[line:96] DEBUG =================扫描程序开始==========================
2019-06-27 16:43:17 logger.py[line:90] ERROR HTTPConnectionPool(host='chrome', port=4444): Max retries exceeded with url: /wd/hub/session (Caused by NewConnectionError('<urllib3.connection.HTTPConnection object at 0x000001E41D6007F0>: Failed to establish a new connection: [Errno 11001] getaddrinfo failed'))
2019-06-27 16:43:22 logger.py[line:90] ERROR 请检查好Chrome环境！
2019-06-27 16:48:53 logger.py[line:96] DEBUG =================扫描程序开始==========================
2019-06-27 16:49:05 logger.py[line:90] ERROR HTTPConnectionPool(host='chrome', port=4444): Max retries exceeded with url: /wd/hub/session (Caused by NewConnectionError('<urllib3.connection.HTTPConnection object at 0x000001D684A4C7B8>: Failed to establish a new connection: [Errno 11001] getaddrinfo failed'))
2019-06-27 16:49:09 logger.py[line:90] ERROR 请检查好Chrome环境！
2019-06-27 16:49:09 logger.py[line:96] DEBUG 扫描http://www.cyzxn.cn/中...
2019-06-27 16:50:35 logger.py[line:96] DEBUG =================扫描程序开始==========================
2019-06-27 16:50:47 logger.py[line:96] DEBUG =================扫描程序开始==========================
2019-06-27 16:50:58 logger.py[line:90] ERROR HTTPConnectionPool(host='chrome', port=4444): Max retries exceeded with url: /wd/hub/session (Caused by NewConnectionError('<urllib3.connection.HTTPConnection object at 0x000001C69E0ED2E8>: Failed to establish a new connection: [Errno 11001] getaddrinfo failed'))
2019-06-27 16:51:03 logger.py[line:90] ERROR 请检查好Chrome环境！
2019-06-27 16:51:03 logger.py[line:96] DEBUG 扫描http://www.cyzxn.cn/中...
2019-06-27 16:51:09 logger.py[line:96] DEBUG 扫描http://www.cyzxn.cn/particulars.html?id=16524&nav_id=0中...
2019-06-27 16:51:10 logger.py[line:96] DEBUG 扫描http://www.cyzxn.cn/particulars.html?id=16523&nav_id=0中...
2019-06-27 16:51:11 logger.py[line:96] DEBUG 扫描http://www.cyzxn.cn/particulars.html?id=16522&nav_id=0中...
2019-06-27 16:51:12 logger.py[line:96] DEBUG 扫描http://www.cyzxn.cn/particulars.html?id=16511&nav_id=0中...
2019-06-27 16:51:13 logger.py[line:96] DEBUG 扫描http://www.cyzxn.cn/particulars.html?id=16510&nav_id=0中...
